2020-05-11 23:05:28 | ERROR | Чат 3e492e4d всё еще не был связан.
2020-05-11 23:05:62 | ERROR | Чат 39ceec24 всё еще не был связан.
2020-05-12 09:05:26 | ERROR | Traceback (most recent call last):
  File "C:\Users\User\Desktop\IDM-master\module\framework\framework\dispatcher.py", line 103, in emulate
    task = (await self._processor(event))
  File "C:\Users\User\Desktop\IDM-master\module\framework\processor.py", line 23, in _processor
    return await handler(event)
  File "C:\Users\User\Desktop\IDM-master\module\framework\handler.py", line 22, in __call__
    return await self.handler(dataclass)
  File "C:\Users\User\Desktop\IDM-master\dutymanager\plugins\base_events\return_user.py", line 23, in add_user
    await bot.api.messages.add_chat_user(
  File "C:\Users\User\AppData\Local\Programs\Python\Python38-32\lib\site-packages\vkbottle\types\methods\messages.py", line 26, in __call__
    return await self.request(
vkbottle.utils.exceptions.VKError: (15, 'Access denied: user already in', <Method MessagesAddChatUser>, {'chat_id': 116, 'user_id': 572178951})

2020-05-12 09:05:56 | ERROR | Traceback (most recent call last):
  File "C:\Users\User\Desktop\IDM-master\module\framework\framework\dispatcher.py", line 103, in emulate
    task = (await self._processor(event))
  File "C:\Users\User\Desktop\IDM-master\module\framework\processor.py", line 23, in _processor
    return await handler(event)
  File "C:\Users\User\Desktop\IDM-master\module\framework\handler.py", line 22, in __call__
    return await self.handler(dataclass)
  File "C:\Users\User\Desktop\IDM-master\dutymanager\plugins\base_events\base_events.py", line 56, in bind_chat
    return await abstract_bind(
  File "C:\Users\User\Desktop\IDM-master\dutymanager\plugins\base_events\base_events.py", line 48, in abstract_bind
    await msg_edit(
IndexError: list index out of range

2020-05-12 09:05:19 | ERROR | Traceback (most recent call last):
  File "C:\Users\User\Desktop\IDM-master\module\framework\framework\dispatcher.py", line 103, in emulate
    task = (await self._processor(event))
  File "C:\Users\User\Desktop\IDM-master\module\framework\processor.py", line 30, in _processor
    return await handler(event, **pattern.dict())
  File "C:\Users\User\Desktop\IDM-master\module\framework\handler.py", line 44, in __call__
    return await self.handler(dataclass, **kwargs)
  File "C:\Users\User\Desktop\IDM-master\dutymanager\plugins\additions\ping.py", line 53, in send_my_signal
    await abstract_ping(
  File "C:\Users\User\Desktop\IDM-master\dutymanager\plugins\additions\ping.py", line 44, in abstract_ping
    await msg_edit(db.chats(uid), message, local_id)
IndexError: list index out of range

2020-05-12 09:05:19 | ERROR | Traceback (most recent call last):
  File "C:\Users\User\Desktop\IDM-master\module\framework\framework\dispatcher.py", line 103, in emulate
    task = (await self._processor(event))
  File "C:\Users\User\Desktop\IDM-master\module\framework\processor.py", line 23, in _processor
    return await handler(event)
  File "C:\Users\User\Desktop\IDM-master\module\framework\handler.py", line 22, in __call__
    return await self.handler(dataclass)
  File "C:\Users\User\Desktop\IDM-master\dutymanager\plugins\base_events\base_events.py", line 56, in bind_chat
    return await abstract_bind(
  File "C:\Users\User\Desktop\IDM-master\dutymanager\plugins\base_events\base_events.py", line 48, in abstract_bind
    await msg_edit(
IndexError: list index out of range

2020-05-12 09:05:44 | ERROR | Чат eeb574b9 всё еще не был связан.
2020-05-12 09:05:28 | ERROR | Traceback (most recent call last):
  File "C:\Users\User\Desktop\IDM-master\module\framework\framework\dispatcher.py", line 103, in emulate
    task = (await self._processor(event))
  File "C:\Users\User\Desktop\IDM-master\module\framework\processor.py", line 23, in _processor
    return await handler(event)
  File "C:\Users\User\Desktop\IDM-master\module\framework\handler.py", line 22, in __call__
    return await self.handler(dataclass)
  File "C:\Users\User\Desktop\IDM-master\dutymanager\plugins\base_events\base_events.py", line 56, in bind_chat
    return await abstract_bind(
  File "C:\Users\User\Desktop\IDM-master\dutymanager\plugins\base_events\base_events.py", line 48, in abstract_bind
    await msg_edit(
IndexError: list index out of range

2020-05-12 09:05:25 | ERROR | Traceback (most recent call last):
  File "C:\Users\User\Desktop\IDM-master\module\framework\framework\dispatcher.py", line 103, in emulate
    task = (await self._processor(event))
  File "C:\Users\User\Desktop\IDM-master\module\framework\processor.py", line 23, in _processor
    return await handler(event)
  File "C:\Users\User\Desktop\IDM-master\module\framework\handler.py", line 22, in __call__
    return await self.handler(dataclass)
  File "C:\Users\User\Desktop\IDM-master\dutymanager\plugins\base_events\base_events.py", line 56, in bind_chat
    return await abstract_bind(
  File "C:\Users\User\Desktop\IDM-master\dutymanager\plugins\base_events\base_events.py", line 48, in abstract_bind
    await msg_edit(
IndexError: list index out of range

2020-05-12 09:05:59 | ERROR | Traceback (most recent call last):
  File "C:\Users\User\Desktop\IDM-master\module\framework\framework\dispatcher.py", line 103, in emulate
    task = (await self._processor(event))
  File "C:\Users\User\Desktop\IDM-master\module\framework\processor.py", line 23, in _processor
    return await handler(event)
  File "C:\Users\User\Desktop\IDM-master\module\framework\handler.py", line 22, in __call__
    return await self.handler(dataclass)
  File "C:\Users\User\Desktop\IDM-master\dutymanager\plugins\base_events\base_events.py", line 56, in bind_chat
    return await abstract_bind(
  File "C:\Users\User\Desktop\IDM-master\dutymanager\plugins\base_events\base_events.py", line 48, in abstract_bind
    await msg_edit(
IndexError: list index out of range

2020-05-12 10:05:53 | ERROR | Traceback (most recent call last):
  File "C:\Users\User\Desktop\IDM-master\module\framework\framework\dispatcher.py", line 103, in emulate
    task = (await self._processor(event))
  File "C:\Users\User\Desktop\IDM-master\module\framework\processor.py", line 23, in _processor
    return await handler(event)
  File "C:\Users\User\Desktop\IDM-master\module\framework\handler.py", line 22, in __call__
    return await self.handler(dataclass)
  File "C:\Users\User\Desktop\IDM-master\dutymanager\plugins\base_events\base_events.py", line 56, in bind_chat
    return await abstract_bind(
  File "C:\Users\User\Desktop\IDM-master\dutymanager\plugins\base_events\base_events.py", line 48, in abstract_bind
    await msg_edit(
IndexError: list index out of range

2020-05-12 10:05:88 | ERROR | Traceback (most recent call last):
  File "C:\Users\User\Desktop\IDM-master\module\framework\framework\dispatcher.py", line 103, in emulate
    task = (await self._processor(event))
  File "C:\Users\User\Desktop\IDM-master\module\framework\processor.py", line 23, in _processor
    return await handler(event)
  File "C:\Users\User\Desktop\IDM-master\module\framework\handler.py", line 22, in __call__
    return await self.handler(dataclass)
  File "C:\Users\User\Desktop\IDM-master\dutymanager\plugins\base_events\base_events.py", line 56, in bind_chat
    return await abstract_bind(
  File "C:\Users\User\Desktop\IDM-master\dutymanager\plugins\base_events\base_events.py", line 48, in abstract_bind
    await msg_edit(
IndexError: list index out of range

2020-05-12 10:05:45 | ERROR | Traceback (most recent call last):
  File "C:\Users\User\Desktop\IDM-master\module\framework\framework\dispatcher.py", line 103, in emulate
    task = (await self._processor(event))
  File "C:\Users\User\Desktop\IDM-master\module\framework\processor.py", line 23, in _processor
    return await handler(event)
  File "C:\Users\User\Desktop\IDM-master\module\framework\handler.py", line 22, in __call__
    return await self.handler(dataclass)
  File "C:\Users\User\Desktop\IDM-master\dutymanager\plugins\base_events\base_events.py", line 56, in bind_chat
    return await abstract_bind(
  File "C:\Users\User\Desktop\IDM-master\dutymanager\plugins\base_events\base_events.py", line 48, in abstract_bind
    await msg_edit(
IndexError: list index out of range

2020-05-12 14:05:69 | ERROR | Traceback (most recent call last):
  File "C:\Users\User\Desktop\IDM-master\module\framework\framework\dispatcher.py", line 103, in emulate
    task = (await self._processor(event))
  File "C:\Users\User\Desktop\IDM-master\module\framework\processor.py", line 30, in _processor
    return await handler(event, **pattern.dict())
  File "C:\Users\User\Desktop\IDM-master\module\framework\handler.py", line 44, in __call__
    return await self.handler(dataclass, **kwargs)
  File "C:\Users\User\Desktop\IDM-master\dutymanager\plugins\base_events\delete_messages.py", line 56, in delete_sms
    if i["from_id"] in user_id and "action" not in i:
TypeError: argument of type 'int' is not iterable

2020-05-12 14:05:14 | ERROR | Traceback (most recent call last):
  File "C:\Users\User\Desktop\IDM-master\module\framework\framework\dispatcher.py", line 103, in emulate
    task = (await self._processor(event))
  File "C:\Users\User\Desktop\IDM-master\module\framework\processor.py", line 30, in _processor
    return await handler(event, **pattern.dict())
  File "C:\Users\User\Desktop\IDM-master\module\framework\handler.py", line 44, in __call__
    return await self.handler(dataclass, **kwargs)
  File "C:\Users\User\Desktop\IDM-master\dutymanager\plugins\base_events\delete_messages.py", line 76, in delete_sms_all
    user_id: str = bot.api.users.get()[0]["id"]
TypeError: 'coroutine' object is not subscriptable

2020-05-12 14:05:86 | ERROR | Traceback (most recent call last):
  File "C:\Users\User\Desktop\IDM-master\module\framework\framework\dispatcher.py", line 103, in emulate
    task = (await self._processor(event))
  File "C:\Users\User\Desktop\IDM-master\module\framework\processor.py", line 30, in _processor
    return await handler(event, **pattern.dict())
  File "C:\Users\User\Desktop\IDM-master\module\framework\handler.py", line 44, in __call__
    return await self.handler(dataclass, **kwargs)
  File "C:\Users\User\Desktop\IDM-master\dutymanager\plugins\base_events\delete_messages.py", line 78, in delete_sms_all
    user_id: str = user_id[0]["id"]
TypeError: 'coroutine' object is not subscriptable

2020-05-12 15:05:71 | ERROR | Traceback (most recent call last):
  File "C:\Users\User\Desktop\IDM-master\module\framework\framework\dispatcher.py", line 103, in emulate
    task = (await self._processor(event))
  File "C:\Users\User\Desktop\IDM-master\module\framework\processor.py", line 30, in _processor
    return await handler(event, **pattern.dict())
  File "C:\Users\User\Desktop\IDM-master\module\framework\handler.py", line 44, in __call__
    return await self.handler(dataclass, **kwargs)
  File "C:\Users\User\Desktop\IDM-master\dutymanager\plugins\base_events\delete_messages.py", line 78, in delete_sms_all
    user_id: str = user_id["id"]
TypeError: 'coroutine' object is not subscriptable

2020-05-12 15:05:18 | ERROR | Traceback (most recent call last):
  File "C:\Users\User\Desktop\IDM-master\module\framework\framework\dispatcher.py", line 103, in emulate
    task = (await self._processor(event))
  File "C:\Users\User\Desktop\IDM-master\module\framework\processor.py", line 30, in _processor
    return await handler(event, **pattern.dict())
  File "C:\Users\User\Desktop\IDM-master\module\framework\handler.py", line 44, in __call__
    return await self.handler(dataclass, **kwargs)
TypeError: delete_sms_all() missing 1 required positional argument: 'user_id'

2020-05-12 17:05:24 | ERROR | Traceback (most recent call last):
  File "C:\Users\User\Desktop\IDM-master\module\framework\framework\dispatcher.py", line 103, in emulate
    task = (await self._processor(event))
  File "C:\Users\User\Desktop\IDM-master\module\framework\processor.py", line 23, in _processor
    return await handler(event)
  File "C:\Users\User\Desktop\IDM-master\module\framework\handler.py", line 22, in __call__
    return await self.handler(dataclass)
  File "C:\Users\User\Desktop\IDM-master\dutymanager\plugins\base_events\return_user.py", line 23, in add_user
    await bot.api.messages.add_chat_user(
  File "C:\Users\User\AppData\Local\Programs\Python\Python38-32\lib\site-packages\vkbottle\types\methods\messages.py", line 26, in __call__
    return await self.request(
vkbottle.utils.exceptions.VKError: (15, "Access denied: can't add this user", <Method MessagesAddChatUser>, {'chat_id': 163, 'user_id': 569244112})

2020-05-12 21:05:08 | ERROR | Traceback (most recent call last):
  File "C:\Users\User\Desktop\IDM-master\module\framework\framework\dispatcher.py", line 103, in emulate
    task = (await self._processor(event))
  File "C:\Users\User\Desktop\IDM-master\module\framework\processor.py", line 23, in _processor
    return await handler(event)
  File "C:\Users\User\Desktop\IDM-master\module\framework\handler.py", line 22, in __call__
    return await self.handler(dataclass)
  File "C:\Users\User\Desktop\IDM-master\dutymanager\plugins\base_events\return_user.py", line 23, in add_user
    await bot.api.messages.add_chat_user(
  File "C:\Users\User\AppData\Local\Programs\Python\Python38-32\lib\site-packages\vkbottle\types\methods\messages.py", line 26, in __call__
    return await self.request(
vkbottle.utils.exceptions.VKError: (5, 'User authorization failed: invalid session.', <Method MessagesAddChatUser>, {'chat_id': 121, 'user_id': 538142639})

2020-05-12 21:05:51 | ERROR | Traceback (most recent call last):
  File "C:\Users\User\Desktop\IDM-master\module\framework\framework\dispatcher.py", line 103, in emulate
    task = (await self._processor(event))
  File "C:\Users\User\Desktop\IDM-master\module\framework\processor.py", line 23, in _processor
    return await handler(event)
  File "C:\Users\User\Desktop\IDM-master\module\framework\handler.py", line 22, in __call__
    return await self.handler(dataclass)
  File "C:\Users\User\Desktop\IDM-master\dutymanager\plugins\base_events\return_user.py", line 23, in add_user
    await bot.api.messages.add_chat_user(
  File "C:\Users\User\AppData\Local\Programs\Python\Python38-32\lib\site-packages\vkbottle\types\methods\messages.py", line 26, in __call__
    return await self.request(
vkbottle.utils.exceptions.VKError: (5, 'User authorization failed: invalid session.', <Method MessagesAddChatUser>, {'chat_id': 121, 'user_id': 538142639})

2020-05-12 22:05:31 | ERROR | Чат d755e76a всё еще не был связан.
2020-05-12 22:05:81 | ERROR | Traceback (most recent call last):
  File "C:\Users\User\Desktop\IDM-master\dutymanager\plugins\additions\friend.py", line 19, in add_friend
    user_id = re.findall(r'\[id(\d*)\|.*]', text)[0]
IndexError: list index out of range

During handling of the above exception, another exception occurred:

Traceback (most recent call last):
  File "C:\Users\User\Desktop\IDM-master\module\framework\framework\dispatcher.py", line 103, in emulate
    task = (await self._processor(event))
  File "C:\Users\User\Desktop\IDM-master\module\framework\processor.py", line 30, in _processor
    return await handler(event, **pattern.dict())
  File "C:\Users\User\Desktop\IDM-master\module\framework\handler.py", line 44, in __call__
    return await self.handler(dataclass, **kwargs)
  File "C:\Users\User\Desktop\IDM-master\dutymanager\plugins\additions\friend.py", line 22, in add_friend
    user_id = bot.api.users.get(user_id=user_id)[0]["id"]
TypeError: __call__() got an unexpected keyword argument 'user_id'

2020-05-12 22:05:60 | ERROR | Traceback (most recent call last):
  File "C:\Users\User\Desktop\IDM-master\dutymanager\plugins\additions\friend.py", line 19, in add_friend
    user_id = re.findall(r'\[id(\d*)\|.*]', text)[0]
IndexError: list index out of range

During handling of the above exception, another exception occurred:

Traceback (most recent call last):
  File "C:\Users\User\Desktop\IDM-master\module\framework\framework\dispatcher.py", line 103, in emulate
    task = (await self._processor(event))
  File "C:\Users\User\Desktop\IDM-master\module\framework\processor.py", line 30, in _processor
    return await handler(event, **pattern.dict())
  File "C:\Users\User\Desktop\IDM-master\module\framework\handler.py", line 44, in __call__
    return await self.handler(dataclass, **kwargs)
  File "C:\Users\User\Desktop\IDM-master\dutymanager\plugins\additions\friend.py", line 22, in add_friend
    user_id = bot.api.users.get(user_ids=user_id)[0]["id"]
TypeError: 'coroutine' object is not subscriptable

2020-05-12 22:05:07 | ERROR | Traceback (most recent call last):
  File "C:\Users\User\Desktop\IDM-master\module\framework\framework\dispatcher.py", line 103, in emulate
    task = (await self._processor(event))
  File "C:\Users\User\Desktop\IDM-master\module\framework\processor.py", line 30, in _processor
    return await handler(event, **pattern.dict())
  File "C:\Users\User\Desktop\IDM-master\module\framework\handler.py", line 44, in __call__
    return await self.handler(dataclass, **kwargs)
  File "C:\Users\User\Desktop\IDM-master\dutymanager\plugins\additions\friend.py", line 23, in add_friend
    await bot.api.friends.add(user_id=user_id)
  File "C:\Users\User\AppData\Local\Programs\Python\Python38-32\lib\site-packages\vkbottle\types\methods\friends.py", line 27, in __call__
    return await self.request(
vkbottle.utils.exceptions.VKError: (100, 'One of the parameters specified was missing or invalid: user_id not integer', <Method FriendsAdd>, {'user_id': 'id538142639'})

2020-05-12 23:05:16 | ERROR | Traceback (most recent call last):
  File "C:\Users\User\Desktop\IDM-master\module\framework\framework\dispatcher.py", line 103, in emulate
    task = (await self._processor(event))
  File "C:\Users\User\Desktop\IDM-master\module\framework\processor.py", line 30, in _processor
    return await handler(event, **pattern.dict())
  File "C:\Users\User\Desktop\IDM-master\module\framework\handler.py", line 44, in __call__
    return await self.handler(dataclass, **kwargs)
  File "C:\Users\User\Desktop\IDM-master\dutymanager\plugins\additions\friend.py", line 25, in add_friend
    await bot.api.friends.add(user_id=user_id)
  File "C:\Users\User\AppData\Local\Programs\Python\Python38-32\lib\site-packages\vkbottle\types\methods\friends.py", line 27, in __call__
    return await self.request(
vkbottle.utils.exceptions.VKError: (100, 'One of the parameters specified was missing or invalid: user_id not integer', <Method FriendsAdd>, {'user_id': <coroutine object UsersGet.__call__ at 0x0558EF28>})

2020-05-12 23:05:66 | ERROR | Traceback (most recent call last):
  File "C:\Users\User\Desktop\IDM-master\module\framework\framework\dispatcher.py", line 103, in emulate
    task = (await self._processor(event))
  File "C:\Users\User\Desktop\IDM-master\module\framework\processor.py", line 30, in _processor
    return await handler(event, **pattern.dict())
  File "C:\Users\User\Desktop\IDM-master\module\framework\handler.py", line 44, in __call__
    return await self.handler(dataclass, **kwargs)
  File "C:\Users\User\Desktop\IDM-master\dutymanager\plugins\additions\friend.py", line 25, in add_friend
    await bot.api.friends.add(user_id=user_id)
  File "C:\Users\User\AppData\Local\Programs\Python\Python38-32\lib\site-packages\vkbottle\types\methods\friends.py", line 27, in __call__
    return await self.request(
vkbottle.utils.exceptions.VKError: (100, 'One of the parameters specified was missing or invalid: user_id not integer', <Method FriendsAdd>, {'user_id': <coroutine object UsersGet.__call__ at 0x05FB7268>})

2020-05-12 23:05:41 | ERROR | Traceback (most recent call last):
  File "C:\Users\User\Desktop\IDM-master\module\framework\framework\dispatcher.py", line 103, in emulate
    task = (await self._processor(event))
  File "C:\Users\User\Desktop\IDM-master\module\framework\processor.py", line 30, in _processor
    return await handler(event, **pattern.dict())
  File "C:\Users\User\Desktop\IDM-master\module\framework\handler.py", line 44, in __call__
    return await self.handler(dataclass, **kwargs)
  File "C:\Users\User\Desktop\IDM-master\dutymanager\plugins\additions\friend.py", line 25, in add_friend
    await bot.api.friends.add(user_id=user_id)
  File "C:\Users\User\AppData\Local\Programs\Python\Python38-32\lib\site-packages\vkbottle\types\methods\friends.py", line 27, in __call__
    return await self.request(
vkbottle.utils.exceptions.VKError: (100, 'One of the parameters specified was missing or invalid: user_id not integer', <Method FriendsAdd>, {'user_id': <coroutine object UsersGet.__call__ at 0x05B52028>})

2020-05-12 23:05:23 | ERROR | Traceback (most recent call last):
  File "C:\Users\User\Desktop\IDM-master\module\framework\framework\dispatcher.py", line 103, in emulate
    task = (await self._processor(event))
  File "C:\Users\User\Desktop\IDM-master\module\framework\processor.py", line 30, in _processor
    return await handler(event, **pattern.dict())
  File "C:\Users\User\Desktop\IDM-master\module\framework\handler.py", line 44, in __call__
    return await self.handler(dataclass, **kwargs)
  File "C:\Users\User\Desktop\IDM-master\dutymanager\plugins\additions\friend.py", line 25, in add_friend
    await bot.api.friends.add(user_id=user_id)
  File "C:\Users\User\AppData\Local\Programs\Python\Python38-32\lib\site-packages\vkbottle\types\methods\friends.py", line 27, in __call__
    return await self.request(
vkbottle.utils.exceptions.VKError: (100, 'One of the parameters specified was missing or invalid: user_id not integer', <Method FriendsAdd>, {'user_id': <coroutine object UsersGet.__call__ at 0x05442068>})

2020-05-12 23:05:67 | ERROR | Traceback (most recent call last):
  File "C:\Users\User\Desktop\IDM-master\module\framework\framework\dispatcher.py", line 103, in emulate
    task = (await self._processor(event))
  File "C:\Users\User\Desktop\IDM-master\module\framework\processor.py", line 30, in _processor
    return await handler(event, **pattern.dict())
  File "C:\Users\User\Desktop\IDM-master\module\framework\handler.py", line 44, in __call__
    return await self.handler(dataclass, **kwargs)
  File "C:\Users\User\Desktop\IDM-master\dutymanager\plugins\additions\friend.py", line 35, in add_friends
TypeError: 'coroutine' object is not subscriptable

2020-05-12 23:05:04 | ERROR | Traceback (most recent call last):
  File "C:\Users\User\Desktop\IDM-master\module\framework\framework\dispatcher.py", line 103, in emulate
    task = (await self._processor(event))
  File "C:\Users\User\Desktop\IDM-master\module\framework\processor.py", line 30, in _processor
    return await handler(event, **pattern.dict())
  File "C:\Users\User\Desktop\IDM-master\module\framework\handler.py", line 44, in __call__
    return await self.handler(dataclass, **kwargs)
  File "C:\Users\User\Desktop\IDM-master\dutymanager\plugins\additions\friend.py", line 32, in add_friends
    user_id = history['items'][0]['reply_message']['from_id']
TypeError: 'coroutine' object is not subscriptable

2020-05-12 23:05:58 | ERROR | Traceback (most recent call last):
  File "C:\Users\User\Desktop\IDM-master\module\framework\framework\dispatcher.py", line 103, in emulate
    task = (await self._processor(event))
  File "C:\Users\User\Desktop\IDM-master\module\framework\processor.py", line 23, in _processor
    return await handler(event)
  File "C:\Users\User\Desktop\IDM-master\module\framework\handler.py", line 22, in __call__
    return await self.handler(dataclass)
  File "C:\Users\User\Desktop\IDM-master\dutymanager\plugins\base_events\return_user.py", line 13, in ban_expired
    await bot.api.messages.add_chat_user(
  File "C:\Users\User\AppData\Local\Programs\Python\Python38-32\lib\site-packages\vkbottle\types\methods\messages.py", line 26, in __call__
    return await self.request(
vkbottle.utils.exceptions.VKError: (15, "Access denied: can't add this user", <Method MessagesAddChatUser>, {'chat_id': 71, 'user_id': 571865667})

2020-05-12 23:05:43 | ERROR | Traceback (most recent call last):
  File "C:\Users\User\Desktop\IDM-master\module\framework\framework\dispatcher.py", line 103, in emulate
    task = (await self._processor(event))
  File "C:\Users\User\Desktop\IDM-master\module\framework\processor.py", line 23, in _processor
    return await handler(event)
  File "C:\Users\User\Desktop\IDM-master\module\framework\handler.py", line 22, in __call__
    return await self.handler(dataclass)
  File "C:\Users\User\Desktop\IDM-master\dutymanager\plugins\base_events\return_user.py", line 23, in add_user
    await bot.api.messages.add_chat_user(
  File "C:\Users\User\AppData\Local\Programs\Python\Python38-32\lib\site-packages\vkbottle\types\methods\messages.py", line 26, in __call__
    return await self.request(
vkbottle.utils.exceptions.VKError: (15, "Access denied: can't add this user", <Method MessagesAddChatUser>, {'chat_id': 71, 'user_id': 571865667})

2020-05-12 23:05:13 | ERROR | Traceback (most recent call last):
  File "C:\Users\User\Desktop\IDM-master\module\framework\framework\dispatcher.py", line 103, in emulate
    task = (await self._processor(event))
  File "C:\Users\User\Desktop\IDM-master\module\framework\processor.py", line 23, in _processor
    return await handler(event)
  File "C:\Users\User\Desktop\IDM-master\module\framework\handler.py", line 22, in __call__
    return await self.handler(dataclass)
  File "C:\Users\User\Desktop\IDM-master\dutymanager\plugins\base_events\return_user.py", line 13, in ban_expired
    await bot.api.messages.add_chat_user(
  File "C:\Users\User\AppData\Local\Programs\Python\Python38-32\lib\site-packages\vkbottle\types\methods\messages.py", line 26, in __call__
    return await self.request(
vkbottle.utils.exceptions.VKError: (15, "Access denied: can't add this user", <Method MessagesAddChatUser>, {'chat_id': 71, 'user_id': 470568701})

2020-05-12 23:05:69 | ERROR | Traceback (most recent call last):
  File "C:\Users\User\Desktop\IDM-master\module\framework\framework\dispatcher.py", line 103, in emulate
    task = (await self._processor(event))
  File "C:\Users\User\Desktop\IDM-master\module\framework\processor.py", line 23, in _processor
    return await handler(event)
  File "C:\Users\User\Desktop\IDM-master\module\framework\handler.py", line 22, in __call__
    return await self.handler(dataclass)
  File "C:\Users\User\Desktop\IDM-master\dutymanager\plugins\base_events\return_user.py", line 23, in add_user
    await bot.api.messages.add_chat_user(
  File "C:\Users\User\AppData\Local\Programs\Python\Python38-32\lib\site-packages\vkbottle\types\methods\messages.py", line 26, in __call__
    return await self.request(
vkbottle.utils.exceptions.VKError: (15, "Access denied: can't add this user", <Method MessagesAddChatUser>, {'chat_id': 71, 'user_id': 470568701})

2020-05-12 23:05:51 | ERROR | Traceback (most recent call last):
  File "C:\Users\User\Desktop\IDM-master\module\framework\framework\dispatcher.py", line 103, in emulate
    task = (await self._processor(event))
  File "C:\Users\User\Desktop\IDM-master\module\framework\processor.py", line 30, in _processor
    return await handler(event, **pattern.dict())
  File "C:\Users\User\Desktop\IDM-master\module\framework\handler.py", line 44, in __call__
    return await self.handler(dataclass, **kwargs)
  File "C:\Users\User\Desktop\IDM-master\dutymanager\plugins\additions\friend.py", line 52, in add_friends
    user_id = history['items'][0]['reply_message']['from_id']
KeyError: 'reply_message'

2020-05-13 18:05:89 | ERROR | Traceback (most recent call last):
  File "C:\Users\User\Desktop\IDM-master\module\framework\framework\dispatcher.py", line 103, in emulate
    task = (await self._processor(event))
  File "C:\Users\User\Desktop\IDM-master\module\framework\processor.py", line 23, in _processor
    return await handler(event)
  File "C:\Users\User\Desktop\IDM-master\module\framework\handler.py", line 22, in __call__
    return await self.handler(dataclass)
  File "C:\Users\User\Desktop\IDM-master\dutymanager\plugins\base_events\return_user.py", line 23, in add_user
    await bot.api.messages.add_chat_user(
  File "C:\Users\User\AppData\Local\Programs\Python\Python38-32\lib\site-packages\vkbottle\types\methods\messages.py", line 26, in __call__
    return await self.request(
vkbottle.utils.exceptions.VKError: (15, 'Access denied: user already left', <Method MessagesAddChatUser>, {'chat_id': 121, 'user_id': 462981270})

2020-05-13 19:05:60 | ERROR | Traceback (most recent call last):
  File "C:\Users\User\AppData\Local\Programs\Python\Python38-32\lib\site-packages\vkbottle\framework\user\processor.py", line 75, in _processor
    return await self._message_processor(*data)
  File "C:\Users\User\AppData\Local\Programs\Python\Python38-32\lib\site-packages\vkbottle\framework\user\processor.py", line 98, in _message_processor
    data.update(await self.expand_data(update_code, data))
vkbottle.utils.exceptions.VKError: (6, 'Too many requests per second', <Method MessagesGetById>, {'message_ids': 2420726})

2020-05-13 19:05:45 | ERROR | Traceback (most recent call last):
  File "C:\Users\User\AppData\Local\Programs\Python\Python38-32\lib\site-packages\vkbottle\framework\user\processor.py", line 75, in _processor
    return await self._message_processor(*data)
  File "C:\Users\User\AppData\Local\Programs\Python\Python38-32\lib\site-packages\vkbottle\framework\user\processor.py", line 98, in _message_processor
    data.update(await self.expand_data(update_code, data))
vkbottle.utils.exceptions.VKError: (6, 'Too many requests per second', <Method MessagesGetById>, {'message_ids': 2420746})

2020-05-13 19:05:57 | ERROR | Traceback (most recent call last):
  File "C:\Users\User\AppData\Local\Programs\Python\Python38-32\lib\site-packages\vkbottle\framework\user\processor.py", line 75, in _processor
    return await self._message_processor(*data)
  File "C:\Users\User\AppData\Local\Programs\Python\Python38-32\lib\site-packages\vkbottle\framework\user\processor.py", line 98, in _message_processor
    data.update(await self.expand_data(update_code, data))
vkbottle.utils.exceptions.VKError: (6, 'Too many requests per second', <Method MessagesGetById>, {'message_ids': 2420934})

2020-05-13 19:05:99 | ERROR | Traceback (most recent call last):
  File "C:\Users\User\AppData\Local\Programs\Python\Python38-32\lib\site-packages\vkbottle\framework\user\processor.py", line 75, in _processor
    return await self._message_processor(*data)
  File "C:\Users\User\AppData\Local\Programs\Python\Python38-32\lib\site-packages\vkbottle\framework\user\processor.py", line 98, in _message_processor
    data.update(await self.expand_data(update_code, data))
vkbottle.utils.exceptions.VKError: (6, 'Too many requests per second', <Method MessagesGetById>, {'message_ids': 2420963})

2020-05-13 19:05:03 | ERROR | Traceback (most recent call last):
  File "C:\Users\User\AppData\Local\Programs\Python\Python38-32\lib\site-packages\vkbottle\framework\user\processor.py", line 75, in _processor
    return await self._message_processor(*data)
  File "C:\Users\User\AppData\Local\Programs\Python\Python38-32\lib\site-packages\vkbottle\framework\user\processor.py", line 98, in _message_processor
    data.update(await self.expand_data(update_code, data))
vkbottle.utils.exceptions.VKError: (6, 'Too many requests per second', <Method MessagesGetById>, {'message_ids': 2421010})

2020-05-13 19:05:74 | ERROR | Traceback (most recent call last):
  File "C:\Users\User\AppData\Local\Programs\Python\Python38-32\lib\site-packages\vkbottle\framework\user\processor.py", line 75, in _processor
    return await self._message_processor(*data)
  File "C:\Users\User\AppData\Local\Programs\Python\Python38-32\lib\site-packages\vkbottle\framework\user\processor.py", line 98, in _message_processor
    data.update(await self.expand_data(update_code, data))
vkbottle.utils.exceptions.VKError: (6, 'Too many requests per second', <Method MessagesGetById>, {'message_ids': 2421035})

2020-05-13 19:05:70 | ERROR | Traceback (most recent call last):
  File "C:\Users\User\AppData\Local\Programs\Python\Python38-32\lib\site-packages\vkbottle\framework\user\processor.py", line 75, in _processor
    return await self._message_processor(*data)
  File "C:\Users\User\AppData\Local\Programs\Python\Python38-32\lib\site-packages\vkbottle\framework\user\processor.py", line 98, in _message_processor
    data.update(await self.expand_data(update_code, data))
vkbottle.utils.exceptions.VKError: (6, 'Too many requests per second', <Method MessagesGetById>, {'message_ids': 2421064})

2020-05-14 11:05:58 | ERROR | Traceback (most recent call last):
  File "C:\Users\User\Desktop\IDM-master\module\framework\framework\dispatcher.py", line 103, in emulate
    task = (await self._processor(event))
  File "C:\Users\User\Desktop\IDM-master\module\framework\processor.py", line 23, in _processor
    return await handler(event)
  File "C:\Users\User\Desktop\IDM-master\module\framework\handler.py", line 22, in __call__
    return await self.handler(dataclass)
  File "C:\Users\User\Desktop\IDM-master\dutymanager\plugins\base_events\return_user.py", line 23, in add_user
    await bot.api.messages.add_chat_user(
  File "C:\Users\User\AppData\Local\Programs\Python\Python38-32\lib\site-packages\vkbottle\types\methods\messages.py", line 26, in __call__
    return await self.request(
vkbottle.utils.exceptions.VKError: (15, 'Access denied: user already in', <Method MessagesAddChatUser>, {'chat_id': 121, 'user_id': 533167021})

2020-05-14 14:05:20 | ERROR | Traceback (most recent call last):
  File "C:\Users\User\Desktop\IDM-master\module\framework\framework\dispatcher.py", line 103, in emulate
    task = (await self._processor(event))
  File "C:\Users\User\Desktop\IDM-master\module\framework\processor.py", line 30, in _processor
    return await handler(event, **pattern.dict())
  File "C:\Users\User\Desktop\IDM-master\module\framework\handler.py", line 44, in __call__
    return await self.handler(dataclass, **kwargs)
  File "C:\Users\User\Desktop\IDM-master\dutymanager\plugins\additions\conv.py", line 111, in konvs
    reply_message = history['items'][0]['reply_message']['text']
TypeError: 'coroutine' object is not subscriptable

2020-05-14 15:05:41 | ERROR | Traceback (most recent call last):
  File "C:\Users\User\Desktop\IDM-master\module\framework\framework\dispatcher.py", line 103, in emulate
    task = (await self._processor(event))
  File "C:\Users\User\Desktop\IDM-master\module\framework\processor.py", line 30, in _processor
    return await handler(event, **pattern.dict())
  File "C:\Users\User\Desktop\IDM-master\module\framework\handler.py", line 44, in __call__
    return await self.handler(dataclass, **kwargs)
  File "C:\Users\User\Desktop\IDM-master\dutymanager\plugins\additions\conv.py", line 112, in konvs
    reply_message = history['items'][0]['reply_message']['text']
TypeError: 'coroutine' object is not subscriptable

2020-05-14 17:05:34 | ERROR | Traceback (most recent call last):
  File "C:\Users\User\Desktop\IDM-master\module\framework\framework\dispatcher.py", line 103, in emulate
    task = (await self._processor(event))
  File "C:\Users\User\Desktop\IDM-master\module\framework\processor.py", line 23, in _processor
    return await handler(event)
  File "C:\Users\User\Desktop\IDM-master\module\framework\handler.py", line 22, in __call__
    return await self.handler(dataclass)
  File "C:\Users\User\Desktop\IDM-master\dutymanager\plugins\base_events\return_user.py", line 23, in add_user
    await bot.api.messages.add_chat_user(
  File "C:\Users\User\AppData\Local\Programs\Python\Python38-32\lib\site-packages\vkbottle\types\methods\messages.py", line 26, in __call__
    return await self.request(
vkbottle.utils.exceptions.VKError: (15, 'Access denied: user already in', <Method MessagesAddChatUser>, {'chat_id': 121, 'user_id': 375916506})

2020-05-14 17:05:51 | ERROR | Traceback (most recent call last):
  File "C:\Users\User\Desktop\IDM-master\module\framework\framework\dispatcher.py", line 103, in emulate
    task = (await self._processor(event))
  File "C:\Users\User\Desktop\IDM-master\module\framework\processor.py", line 23, in _processor
    return await handler(event)
  File "C:\Users\User\Desktop\IDM-master\module\framework\handler.py", line 22, in __call__
    return await self.handler(dataclass)
  File "C:\Users\User\Desktop\IDM-master\dutymanager\plugins\base_events\return_user.py", line 23, in add_user
    await bot.api.messages.add_chat_user(
  File "C:\Users\User\AppData\Local\Programs\Python\Python38-32\lib\site-packages\vkbottle\types\methods\messages.py", line 26, in __call__
    return await self.request(
vkbottle.utils.exceptions.VKError: (15, 'Access denied: user already in', <Method MessagesAddChatUser>, {'chat_id': 121, 'user_id': 375916506})

2020-05-14 17:05:52 | ERROR | Traceback (most recent call last):
  File "C:\Users\User\Desktop\IDM-master\module\framework\framework\dispatcher.py", line 103, in emulate
    task = (await self._processor(event))
  File "C:\Users\User\Desktop\IDM-master\module\framework\processor.py", line 23, in _processor
    return await handler(event)
  File "C:\Users\User\Desktop\IDM-master\module\framework\handler.py", line 22, in __call__
    return await self.handler(dataclass)
  File "C:\Users\User\Desktop\IDM-master\dutymanager\plugins\base_events\return_user.py", line 23, in add_user
    await bot.api.messages.add_chat_user(
  File "C:\Users\User\AppData\Local\Programs\Python\Python38-32\lib\site-packages\vkbottle\types\methods\messages.py", line 26, in __call__
    return await self.request(
vkbottle.utils.exceptions.VKError: (15, "Access denied: can't add this user", <Method MessagesAddChatUser>, {'chat_id': 121, 'user_id': 597358861})

2020-05-14 19:05:17 | ERROR | Traceback (most recent call last):
  File "C:\Users\User\Desktop\IDM-master\module\framework\framework\dispatcher.py", line 103, in emulate
    task = (await self._processor(event))
  File "C:\Users\User\Desktop\IDM-master\module\framework\processor.py", line 30, in _processor
    return await handler(event, **pattern.dict())
  File "C:\Users\User\Desktop\IDM-master\module\framework\handler.py", line 44, in __call__
    return await self.handler(dataclass, **kwargs)
  File "C:\Users\User\Desktop\IDM-master\dutymanager\plugins\additions\bomb.py", line 18, in bomb
    worker.manage_worker("bomb", start=True)
NameError: name 'worker' is not defined

2020-05-14 19:05:11 | ERROR | Traceback (most recent call last):
  File "C:\Users\User\Desktop\IDM-master\module\framework\framework\dispatcher.py", line 103, in emulate
    task = (await self._processor(event))
  File "C:\Users\User\Desktop\IDM-master\module\framework\processor.py", line 30, in _processor
    return await handler(event, **pattern.dict())
  File "C:\Users\User\Desktop\IDM-master\module\framework\handler.py", line 44, in __call__
    return await self.handler(dataclass, **kwargs)
  File "C:\Users\User\Desktop\IDM-master\dutymanager\plugins\additions\bomb.py", line 22, in bomb
    if len(time) == 2:
TypeError: object of type 'int' has no len()

2020-05-14 19:05:38 | ERROR | Traceback (most recent call last):
  File "C:\Users\User\Desktop\IDM-master\module\framework\framework\dispatcher.py", line 103, in emulate
    task = (await self._processor(event))
  File "C:\Users\User\Desktop\IDM-master\module\framework\processor.py", line 30, in _processor
    return await handler(event, **pattern.dict())
  File "C:\Users\User\Desktop\IDM-master\module\framework\handler.py", line 44, in __call__
    return await self.handler(dataclass, **kwargs)
  File "C:\Users\User\Desktop\IDM-master\dutymanager\plugins\additions\bomb.py", line 22, in bomb
    if len(time) == 2:
TypeError: object of type 'int' has no len()

2020-05-14 20:05:34 | ERROR | Traceback (most recent call last):
  File "C:\Users\User\Desktop\IDM-master\module\framework\framework\dispatcher.py", line 103, in emulate
    task = (await self._processor(event))
  File "C:\Users\User\Desktop\IDM-master\module\framework\processor.py", line 30, in _processor
    return await handler(event, **pattern.dict())
  File "C:\Users\User\Desktop\IDM-master\module\framework\handler.py", line 44, in __call__
    return await self.handler(dataclass, **kwargs)
  File "C:\Users\User\Desktop\IDM-master\dutymanager\plugins\additions\bomb.py", line 31, in bomb
    await bot.api.messages.delete(
  File "C:\Users\User\AppData\Local\Programs\Python\Python38-32\lib\site-packages\vkbottle\types\methods\messages.py", line 110, in __call__
    return await self.request(
vkbottle.utils.exceptions.VKError: (924, "Can't delete this message for everybody", <Method MessagesDelete>, {'message_ids': '2699', 'spam': 0, 'delete_for_all': True})

2020-05-14 20:05:71 | ERROR | Traceback (most recent call last):
  File "C:\Users\User\Desktop\IDM-master\module\framework\framework\dispatcher.py", line 103, in emulate
    task = (await self._processor(event))
  File "C:\Users\User\Desktop\IDM-master\module\framework\processor.py", line 30, in _processor
    return await handler(event, **pattern.dict())
  File "C:\Users\User\Desktop\IDM-master\module\framework\handler.py", line 44, in __call__
    return await self.handler(dataclass, **kwargs)
  File "C:\Users\User\Desktop\IDM-master\dutymanager\plugins\additions\bomb.py", line 18, in bomb
    local_id = history['items'][0]['id']
TypeError: 'coroutine' object is not subscriptable

2020-05-14 20:05:07 | ERROR | Traceback (most recent call last):
  File "C:\Users\User\Desktop\IDM-master\module\framework\framework\dispatcher.py", line 103, in emulate
    task = (await self._processor(event))
  File "C:\Users\User\Desktop\IDM-master\module\framework\processor.py", line 30, in _processor
    return await handler(event, **pattern.dict())
  File "C:\Users\User\Desktop\IDM-master\module\framework\handler.py", line 44, in __call__
    return await self.handler(dataclass, **kwargs)
  File "C:\Users\User\Desktop\IDM-master\dutymanager\plugins\additions\bomb.py", line 32, in bomb
    await bot.api.messages.delete(
  File "C:\Users\User\AppData\Local\Programs\Python\Python38-32\lib\site-packages\vkbottle\types\methods\messages.py", line 110, in __call__
    return await self.request(
vkbottle.utils.exceptions.VKError: (924, "Can't delete this message for everybody", <Method MessagesDelete>, {'message_ids': '2459299', 'spam': 0, 'delete_for_all': True})

2020-05-14 21:05:47 | ERROR | Traceback (most recent call last):
  File "C:\Users\User\Desktop\IDM-master\module\framework\framework\dispatcher.py", line 103, in emulate
    task = (await self._processor(event))
  File "C:\Users\User\Desktop\IDM-master\module\framework\processor.py", line 29, in _processor
    if self.patcher.check(text, pattern) is not None:
  File "C:\Users\User\AppData\Local\Programs\Python\Python38-32\lib\site-packages\vbml\patcher\patcher.py", line 67, in check
    raise ValueError(f"Unknown validator: {validator}")
ValueError: Unknown validator: unix

2020-05-14 22:05:02 | ERROR | Traceback (most recent call last):
  File "C:\Users\User\Desktop\IDM-master\module\framework\framework\dispatcher.py", line 103, in emulate
    task = (await self._processor(event))
  File "C:\Users\User\Desktop\IDM-master\module\framework\processor.py", line 29, in _processor
    if self.patcher.check(text, pattern) is not None:
  File "C:\Users\User\AppData\Local\Programs\Python\Python38-32\lib\site-packages\vbml\patcher\patcher.py", line 67, in check
    raise ValueError(f"Unknown validator: {validator}")
ValueError: Unknown validator: unix

2020-05-14 22:05:04 | ERROR | Traceback (most recent call last):
  File "C:\Users\User\Desktop\IDM-master\module\framework\framework\dispatcher.py", line 103, in emulate
    task = (await self._processor(event))
  File "C:\Users\User\Desktop\IDM-master\module\framework\processor.py", line 29, in _processor
    if self.patcher.check(text, pattern) is not None:
  File "C:\Users\User\AppData\Local\Programs\Python\Python38-32\lib\site-packages\vbml\patcher\patcher.py", line 67, in check
    raise ValueError(f"Unknown validator: {validator}")
ValueError: Unknown validator: unix

2020-05-14 22:05:07 | ERROR | Traceback (most recent call last):
  File "C:\Users\User\Desktop\IDM-master\module\framework\framework\dispatcher.py", line 103, in emulate
    task = (await self._processor(event))
  File "C:\Users\User\Desktop\IDM-master\module\framework\processor.py", line 23, in _processor
    return await handler(event)
  File "C:\Users\User\Desktop\IDM-master\module\framework\handler.py", line 22, in __call__
    return await self.handler(dataclass)
  File "C:\Users\User\Desktop\IDM-master\dutymanager\plugins\base_events\return_user.py", line 23, in add_user
    await bot.api.messages.add_chat_user(
  File "C:\Users\User\AppData\Local\Programs\Python\Python38-32\lib\site-packages\vkbottle\types\methods\messages.py", line 26, in __call__
    return await self.request(
vkbottle.utils.exceptions.VKError: (15, "Access denied: can't add this user", <Method MessagesAddChatUser>, {'chat_id': 71, 'user_id': 575905484})

